<?xml version="1.0" encoding="utf-8"?>
<!-- This URDF was automatically created by SolidWorks to URDF Exporter! Originally created by Stephen Brawner (brawner@gmail.com) 
     Commit Version: 1.6.0-1-g15f4949  Build Version: 1.6.7594.29634
     For more information, please see http://wiki.ros.org/sw_urdf_exporter -->
<robot
  name="hunter2_base" xmlns:xacro="http://ros.org/wiki/xacro">
  <link
    name="base_link">
    <inertial>
      <origin
        xyz="0.0266989327622036 0.000409203500587652 -0.135901124750884"
        rpy="0 0 0" />
      <mass
        value="1.02945169536679" />
      <inertia
        ixx="0.0332370959804736"
        ixy="-1.013150489971E-06"
        ixz="-0.00188859201421112"
        iyy="0.111072002332437"
        iyz="-5.13308150598312E-07"
        izz="0.12660862809283" />
    </inertial>
    <visual>
      <origin
        xyz="0 0 0"
        rpy="0 0 0" />
      <geometry>
        <mesh
          filename="package://hunter2_base/meshes/base_link.STL" />
      </geometry>
      <material
        name="">
        <color
          rgba="0.792156862745098 0.819607843137255 0.933333333333333 1" />
      </material>
    </visual>
    <collision>
      <origin
        xyz="0 0 0"
        rpy="0 0 0" />
      <geometry>
        <mesh
          filename="package://hunter2_base/meshes/base_link.STL" />
      </geometry>
    </collision>
  </link>
  <link
    name="front_steer_left_link">
    <inertial>
      <origin
        xyz="-0.012614 1.8116E-05 0.0023132"
        rpy="0 0 0" />
      <mass
        value="0.8526" />
      <inertia
        ixx="0.063827"
        ixy="1.5154E-07"
        ixz="3.1921E-07"
        iyy="0.063827"
        iyz="2.9854E-08"
        izz="0.11091" />
    </inertial>
    <visual>
      <origin
        xyz="0 0 0"
        rpy="0 0 0" />
      <geometry>
      <cylinder length="0.001" radius="0.005"/>
      </geometry>
      <material
        name="">
        <color
          rgba="0.79216 0.81961 0.93333 1" />
      </material>
    </visual>
    <collision>
      <origin
        xyz="0 0 0"
        rpy="0 0 0" />
      <geometry>
      <cylinder length="0.001" radius="0.005"/>
      </geometry>
    </collision>
  </link>
  <joint
    name="front_steer_left_joint"
    type="revolute">
    <origin
      xyz="0.37142 0.29199 -0.1955"
      rpy="1.5708 0 0" />
    <parent
      link="base_link" />
    <child
      link="front_steer_left_link" />
    <axis
      xyz="0 1 0" />
    <limit
      lower="-0.69"
      upper="0.69"
      effort="0"
      velocity="0" />
  </joint>
  <link
    name="front_left_wheel_link">
    <inertial>
      <origin
        xyz="-6.5774E-06 2.0242E-05 -0.0096386"
        rpy="0 0 0" />
      <mass
        value="0.7007" />
      <inertia
        ixx="0.063724"
        ixy="-3.8745E-08"
        ixz="2.2753E-07"
        iyy="0.063724"
        iyz="-4.88E-08"
        izz="0.11072" />
    </inertial>
    <visual>
      <origin
        xyz="0 0 0"
        rpy="0 0 0" />
      <geometry>
        <mesh
          filename="package://hunter2_base/meshes/front_left_wheel_link.STL" />
      </geometry>
      <material
        name="">
        <color
          rgba="0.79216 0.81961 0.93333 1" />
      </material>
    </visual>
    <collision>
      <origin
        xyz="0 0 0"
        rpy="0 0 0" />
      <geometry>
        <mesh
          filename="package://hunter2_base/meshes/front_left_wheel_link.STL" />
      </geometry>
    </collision>
  </link>
  <joint
    name="front_left_wheel_joint"
    type="continuous">
    <origin
      xyz="0 0 0"
      rpy="0 0 0" />
    <parent
      link="front_steer_left_link" />
    <child
      link="front_left_wheel_link" />
    <axis
      xyz="0 0 -1" />
  </joint>
  <link
    name="front_steer_right_link">
    <inertial>
      <origin
        xyz="-8.9374E-08 1.0997E-07 0.0095958"
        rpy="0 0 0" />
      <mass
        value="0.696" />
      <inertia
        ixx="0.063704"
        ixy="-6.3892E-08"
        ixz="-2.0159E-08"
        iyy="0.063704"
        iyz="6.4721E-08"
        izz="0.11068" />
    </inertial>
    <visual>
      <origin
        xyz="0 0 0"
        rpy="0 0 0" />
      <geometry>
      <cylinder length="0.001" radius="0.005"/>
      </geometry>
      <material
        name="">
        <color
          rgba="0.79216 0.81961 0.93333 1" />
      </material>
    </visual>
    <collision>
      <origin
        xyz="0 0 0"
        rpy="0 0 0" />
      <geometry>
      <cylinder length="0.001" radius="0.005"/>
      </geometry>
    </collision>
  </link>
  <joint
    name="front_steer_right_joint"
    type="revolute">
    <origin
      xyz="0.37142 -0.29201 -0.1955"
      rpy="1.5708 0 0" />
    <parent
      link="base_link" />
    <child
      link="front_steer_right_link" />
    <axis
      xyz="0 1 0" />
    <limit
      lower="-0.69"
      upper="0.69"
      effort="0"
      velocity="0" />
  </joint>
  <link
    name="front_right_wheel_link">
    <inertial>
      <origin
        xyz="-9.1148E-08 1.1284E-07 0.0095049"
        rpy="0 0 0" />
      <mass
        value="0.5613" />
      <inertia
        ixx="0.063626"
        ixy="-6.4092E-08"
        ixz="-2.0164E-08"
        iyy="0.063626"
        iyz="6.4721E-08"
        izz="0.11054" />
    </inertial>
    <visual>
      <origin
        xyz="0 0 0"
        rpy="0 3.14 0" />
      <geometry>
        <mesh
          filename="package://hunter2_base/meshes/front_left_wheel_link.STL" />
      </geometry>
      <material
        name="">
        <color
          rgba="0.79216 0.81961 0.93333 1" />
      </material>
    </visual>
    <collision>
      <origin
        xyz="0 0 0"
        rpy="0 0 0" />
      <geometry>
        <mesh
          filename="package://hunter2_base/meshes/front_right_wheel_link.STL" />
      </geometry>
    </collision>
  </link>
  <joint
    name="front_right_wheel_joint"
    type="continuous">
    <origin
      xyz="0 0 0"
      rpy="0 0 0" />
    <parent
      link="front_steer_right_link" />
    <child
      link="front_right_wheel_link" />
    <axis
      xyz="0 0 -1" />
  </joint>
  <link
    name="left_rear_link">
    <inertial>
      <origin
        xyz="-8.826E-05 6.4342E-05 -0.0096491"
        rpy="0 0 0" />
      <mass
        value="0.6692" />
      <inertia
        ixx="0.063699"
        ixy="-2.542E-07"
        ixz="2.638E-08"
        iyy="0.063699"
        iyz="-5.9934E-08"
        izz="0.11067" />
    </inertial>
    <visual>
      <origin
        xyz="0 0 0"
        rpy="0 0 0" />
      <geometry>
        <mesh
          filename="package://hunter2_base/meshes/left_rear_link.STL" />
      </geometry>
      <material
        name="">
        <color
          rgba="0.79216 0.81961 0.93333 1" />
      </material>
    </visual>
    <collision>
      <origin
        xyz="0 0 0"
        rpy="0 0 0" />
      <geometry>
        <mesh
          filename="package://hunter2_base/meshes/left_rear_link.STL" />
      </geometry>
    </collision>
  </link>
  <joint
    name="left_rear_joint"
    type="continuous">
    <origin
      xyz="-0.28 0.29249 -0.19558"
      rpy="1.5708 0 0" />
    <parent
      link="base_link" />
    <child
      link="left_rear_link" />
    <axis
      xyz="0 0 -1" />
    <limit
      lower="-3.14"
      upper="3.14"
      effort="0"
      velocity="0" />
  </joint>
  <link
    name="right_rear_link">
    <inertial>
      <origin
        xyz="8.6344E-05 7.4488E-05 0.0097824"
        rpy="0 0 0" />
      <mass
        value="0.7133" />
      <inertia
        ixx="0.06373"
        ixy="2.5408E-07"
        ixz="2.6379E-08"
        iyy="0.06373"
        iyz="5.9941E-08"
        izz="0.11073" />
    </inertial>
    <visual>
      <origin
        xyz="0 0 0"
        rpy="0 0 0" />
      <geometry>
        <mesh
          filename="package://hunter2_base/meshes/right_rear_link.STL" />
      </geometry>
      <material
        name="">
        <color
          rgba="0.79216 0.81961 0.93333 1" />
      </material>
    </visual>
    <collision>
      <origin
        xyz="0 0 0"
        rpy="0 0 0" />
      <geometry>
        <mesh
          filename="package://hunter2_base/meshes/right_rear_link.STL" />
      </geometry>
    </collision>
  </link>
  <joint
    name="right_rear_joint"
    type="continuous">
    <origin
      xyz="-0.28018 -0.29251 -0.19558"
      rpy="1.5708 0.0026575 0" />
    <parent
      link="base_link" />
    <child
      link="right_rear_link" />
    <axis
      xyz="0 0 -1" />
    <limit
      lower="-3.14"
      upper="3.14"
      effort="0"
      velocity="0" />
  </joint>
  <link
    name="front_steer_link">
    <inertial>
      <origin
        xyz="0.049836 8.1046E-15 0.017912"
        rpy="0 0 0" />
      <mass
        value="0.0049179" />
      <inertia
        ixx="1.6846E-07"
        ixy="7.6396E-23"
        ixz="-1.0974E-08"
        iyy="7.549E-07"
        iyz="-1.8957E-22"
        izz="7.334E-07" />
    </inertial>
    <visual>
      <origin
        xyz="0 0 0"
        rpy="0 0 0" />
      <geometry>
      <cylinder length="0.001" radius="0.005"/>
      </geometry>
      <material
        name="">
        <color
          rgba="0.79216 0.81961 0.93333 1" />
      </material>
    </visual>
    <collision>
      <origin
        xyz="0 0 0"
        rpy="0 0 0" />
      <geometry>
      <cylinder length="0.001" radius="0.005"/>
      </geometry>
    </collision>
  </link>
  <joint
    name="front_steer_joint"
    type="revolute">
    <origin
      xyz="0.44792 -1.1431E-05 -0.121"
      rpy="0 0 0" />
    <parent
      link="base_link" />
    <child
      link="front_steer_link" />
    <axis
      xyz="0 0 1" />
    <limit
      lower="-0.72"
      upper="0.72"
      effort="0"
      velocity="0" />
  </joint>
  <link
    name="rear_wheel_link">
<inertial>
      <origin
        xyz="-0.02 0.0031269 -0.12735"
        rpy="0 0 0" />
      <mass
        value="0.0049179" />
      <inertia
        ixx="1.1821E-06"
        ixy="9.6965E-13"
        ixz="-3.1553E-12"
        iyy="9.5276E-07"
        iyz="1.2428E-08"
        izz="1.0913E-06" />
    </inertial>
    <visual>
      <origin
        xyz="0 0 0"
        rpy="0 0 0" />
      <geometry>
      <cylinder length="0.001" radius="0.005"/>
      </geometry>
      <material
        name="">
        <color
          rgba="1 1 1 1" />
      </material>
    </visual>
    <collision>
      <origin
        xyz="0 0 0"
        rpy="0 0 0" />
      <geometry>
      <cylinder length="0.001" radius="0.005"/>
      </geometry>
    </collision>
  </link>
  <joint
    name="rear_wheel_joint"
    type="continuous">
    <origin
      xyz="-0.42408 -1.1431E-05 -0.085581"
      rpy="0.0032313 0 0" />
    <parent
      link="base_link" />
    <child
      link="rear_wheel_link" />
    <axis
      xyz="0 0 1" />
  </joint>
  
  <gazebo reference="front_left_wheel_link"> 
      <material>Gazebo/Grey </material>
      </gazebo>
  <gazebo reference="front_right_wheel_link"> 
      <material>Gazebo/Grey </material>
      </gazebo>
  <gazebo reference="right_rear_link"> 
      <material>Gazebo/Grey </material>
      </gazebo>
  <gazebo reference="left_rear_link"> 
      <material>Gazebo/Grey </material>
      </gazebo>

  <gazebo>
    <plugin name="gazebo_ros_control" filename="libgazebo_ros_control.so">
      <robotSimType>steer_bot_hardware_gazebo/SteerBotHardwareGazebo</robotSimType>
      <legacyModeNS>false</legacyModeNS>
    </plugin>
  </gazebo>

  <!-- gazebo sensors -->

  <gazebo>
    <plugin name="imu_controller" filename="libhector_gazebo_ros_imu.so">
      <updateRate>50.0</updateRate>
      <bodyName>base_link</bodyName>
      <topicName>imu/data</topicName>
      <accelDrift>0.005 0.005 0.005</accelDrift>
      <accelGaussianNoise>0.005 0.005 0.005</accelGaussianNoise>
      <rateDrift>0.005 0.005 0.005 </rateDrift>
      <rateGaussianNoise>0.005 0.005 0.005 </rateGaussianNoise>
      <headingDrift>0.005</headingDrift>
      <headingGaussianNoise>0.005</headingGaussianNoise>
    </plugin>
  </gazebo>

  <gazebo>
    <plugin name="gps_controller" filename="libhector_gazebo_ros_gps.so">
      <updateRate>40</updateRate>
      <bodyName>base_link</bodyName>
      <frameId>base_link</frameId>
      <topicName>navsat/fix</topicName>
      <velocityTopicName>navsat/vel</velocityTopicName>
      <referenceLatitude>53.268598</referenceLatitude> <!-- 49.9 -->
      <referenceLongitude>-0.524198</referenceLongitude><!-- 8.9 -->
      <referenceHeading>0</referenceHeading>
      <referenceAltitude>0</referenceAltitude>
      <drift>0.0001 0.0001 0.0001</drift>
    </plugin>
  </gazebo>

  <xacro:include filename="$(find hunter2_base)/urdf/hunter2_with_sensors/intel_realsense_color_stereo.urdf.xacro"/>

  <link name="realsense_mountpoint"/>
  <joint name="realsense_mountpoint_joint" type="fixed">
    <origin xyz="0.51 0 0" rpy="0 0 0" />
    <parent link="base_link"/>
    <child link="realsense_mountpoint" />
  </joint>
  <xacro:intel_realsense_mount prefix="camera" topic="realsense" parent_link="realsense_mountpoint"/>

  <link name="realsense_rear_mountpoint"/>
  <joint name="realsense_rear_mountpoint_joint" type="fixed">
    <origin xyz="-0.41 0 0" rpy="0 0 3.14159" />
    <parent link="base_link"/>
    <child link="realsense_rear_mountpoint" />
  </joint>
  <xacro:intel_realsense_mount prefix="camera_rear" topic="realsense_rear" parent_link="realsense_rear_mountpoint"/>
 
  <!--<link name="lidar_link">
    <visual>
      <origin xyz="0 0 0" rpy="0 0 0"/>
      <geometry>
        <cylinder length="0.04" radius="0.03"/>
      </geometry>
      <material name="light_black"/>
    </visual>
    <inertial>
      <origin xyz="0 0 0" />
      <mass value="0.220" />
      <inertia ixx="1.214e-4"
               ixy="0.0" iyy="1.214e-4"
               ixz="0.0" iyz="0.0" izz="1.597e-4" />
    </inertial>
  </link>
  
  <joint name="lidar_link_joint" type="fixed">
    <parent link="base_link"/>
    <child link="lidar_link"/>
    <origin xyz="0.105 0 0.02" rpy="0 0 3.14159"/>
  </joint>

  <gazebo reference="lidar_link">
    <sensor name="gazebo_lidar" type="ray">
      <update_rate>12.0</update_rate>
      <plugin name="gazebo_lidar" filename="libgazebo_ros_laser.so">
        <topicName>scan</topicName>
        <namespace></namespace>
        <outputType>sensor_msgs/LaserScan</outputType>
        <frameName>lidar_link</frameName>
      </plugin>
      <ray>
        <scan>
          <horizontal>
            <samples>360</samples>
            <resolution>1</resolution>
            <min_angle>-3.14159</min_angle>
            <max_angle>3.14159</max_angle>
          </horizontal>
        </scan>
        <range>
          <min>0.120</min>
          <max>20</max>
          <resolution>0.015</resolution>
        </range>
        <noise>
          <type>gaussian</type>
          <mean>0.0</mean>
          <stddev>0.01</stddev>
        </noise>
      </ray>
    </sensor>
    <material>Gazebo/DarkGrey</material>
  </gazebo>-->

</robot>
